<sdf version='1.7'>
  <world name='default'>
    <light name='sun' type='directional'>
      <cast_shadows>1</cast_shadows>
      <pose>0 0 10 0 -0 0</pose>
      <diffuse>0.8 0.8 0.8 1</diffuse>
      <specular>0.2 0.2 0.2 1</specular>
      <attenuation>
        <range>1000</range>
        <constant>0.9</constant>
        <linear>0.01</linear>
        <quadratic>0.001</quadratic>
      </attenuation>
      <direction>-0.5 0.1 -0.9</direction>
      <spot>
        <inner_angle>0</inner_angle>
        <outer_angle>0</outer_angle>
        <falloff>0</falloff>
      </spot>
    </light>
    <model name='ground_plane'>
      <static>1</static>
      <link name='link'>
        <collision name='collision'>
          <geometry>
            <plane>
              <normal>0 0 1</normal>
              <size>100 100</size>
            </plane>
          </geometry>
          <surface>
            <contact>
              <collide_bitmask>65535</collide_bitmask>
              <ode/>
            </contact>
            <friction>
              <ode>
                <mu>100</mu>
                <mu2>50</mu2>
              </ode>
              <torsional>
                <ode/>
              </torsional>
            </friction>
            <bounce/>
          </surface>
          <max_contacts>10</max_contacts>
        </collision>
        <visual name='visual'>
          <cast_shadows>0</cast_shadows>
          <geometry>
            <plane>
              <normal>0 0 1</normal>
              <size>100 100</size>
            </plane>
          </geometry>
          <material>
            <script>
              <uri>file://media/materials/scripts/gazebo.material</uri>
              <name>Gazebo/Grey</name>
            </script>
          </material>
        </visual>
        <self_collide>0</self_collide>
        <enable_wind>0</enable_wind>
        <kinematic>0</kinematic>
      </link>
    </model>
    <gravity>0 0 -9.8</gravity>
    <magnetic_field>6e-06 2.3e-05 -4.2e-05</magnetic_field>
    <atmosphere type='adiabatic'/>
    <physics type='ode'>
      <max_step_size>0.001</max_step_size>
      <real_time_factor>1</real_time_factor>
      <real_time_update_rate>1000</real_time_update_rate>
    </physics>
    <scene>
      <ambient>0.4 0.4 0.4 1</ambient>
      <background>0.7 0.7 0.7 1</background>
      <shadows>1</shadows>
    </scene>
    <audio>
      <device>default</device>
    </audio>
    <wind/>
    <spherical_coordinates>
      <surface_model>EARTH_WGS84</surface_model>
      <latitude_deg>0</latitude_deg>
      <longitude_deg>0</longitude_deg>
      <elevation>0</elevation>
      <heading_deg>0</heading_deg>
    </spherical_coordinates>
    <model name='ros2_ws'>
      <link name='base_link'>
        <inertial>
          <pose>0.212828 4e-06 0.090281 0 -0 0</pose>
          <mass>13.112</mass>
          <inertia>
            <ixx>0.231664</ixx>
            <ixy>-1.16086e-05</ixy>
            <ixz>0.0239536</ixz>
            <iyy>0.312785</iyy>
            <iyz>2.01407e-06</iyz>
            <izz>0.366143</izz>
          </inertia>
        </inertial>
        <collision name='base_link_fixed_joint_lump__chassis_collision'>
          <pose>0.2 0 0.075 0 -0 0</pose>
          <geometry>
            <box>
              <size>0.5 0.3 0.15</size>
            </box>
          </geometry>
          <surface>
            <contact>
              <ode/>
            </contact>
            <friction>
              <ode/>
              <torsional>
                <ode/>
              </torsional>
            </friction>
            <bounce/>
          </surface>
          <max_contacts>10</max_contacts>
        </collision>
        <collision name='base_link_fixed_joint_lump__back_collision_1'>
          <pose>0.15 0 0.22 0 -0 0</pose>
          <geometry>
            <box>
              <size>0.25 0.25 0.14</size>
            </box>
          </geometry>
          <surface>
            <contact>
              <ode/>
            </contact>
            <friction>
              <ode/>
              <torsional>
                <ode/>
              </torsional>
            </friction>
            <bounce/>
          </surface>
          <max_contacts>10</max_contacts>
        </collision>
        <collision name='base_link_fixed_joint_lump__laser_framenew_collision_2'>
          <pose>0.45 0 0.02 0 -0 0</pose>
          <geometry>
            <cylinder>
              <length>0.01</length>
              <radius>0.01</radius>
            </cylinder>
          </geometry>
          <surface>
            <contact>
              <ode/>
            </contact>
            <friction>
              <ode/>
              <torsional>
                <ode/>
              </torsional>
            </friction>
            <bounce/>
          </surface>
          <max_contacts>10</max_contacts>
        </collision>
        <collision name='base_link_fixed_joint_lump__support_collision_3'>
          <pose>0.37 0 0.16 0 -0 0</pose>
          <geometry>
            <cylinder>
              <length>0.02</length>
              <radius>0.025</radius>
            </cylinder>
          </geometry>
          <surface>
            <contact>
              <ode/>
            </contact>
            <friction>
              <ode/>
              <torsional>
                <ode/>
              </torsional>
            </friction>
            <bounce/>
          </surface>
          <max_contacts>10</max_contacts>
        </collision>
        <collision name='base_link_fixed_joint_lump__support1_collision_4'>
          <pose>0.37 0 0.26 0 -0 0</pose>
          <geometry>
            <cylinder>
              <length>0.18</length>
              <radius>0.025</radius>
            </cylinder>
          </geometry>
          <surface>
            <contact>
              <ode/>
            </contact>
            <friction>
              <ode/>
              <torsional>
                <ode/>
              </torsional>
            </friction>
            <bounce/>
          </surface>
          <max_contacts>10</max_contacts>
        </collision>
        <collision name='base_link_fixed_joint_lump__box_collision_5'>
          <pose>0.37 0 0.38 0 -0 0</pose>
          <geometry>
            <box>
              <size>0.06 0.12 0.06</size>
            </box>
          </geometry>
          <surface>
            <contact>
              <ode/>
            </contact>
            <friction>
              <ode/>
              <torsional>
                <ode/>
              </torsional>
            </friction>
            <bounce/>
          </surface>
          <max_contacts>10</max_contacts>
        </collision>
        <collision name='base_link_fixed_joint_lump__laser_frame_collision_6'>
          <pose>0.37 0 0.42 0 -0 0</pose>
          <geometry>
            <cylinder>
              <length>0.02</length>
              <radius>0.02</radius>
            </cylinder>
          </geometry>
          <surface>
            <contact>
              <ode/>
            </contact>
            <friction>
              <ode/>
              <torsional>
                <ode/>
              </torsional>
            </friction>
            <bounce/>
          </surface>
          <max_contacts>10</max_contacts>
        </collision>
        <collision name='base_link_fixed_joint_lump__vc2_collision_7'>
          <pose>0.445 0.05 0.05 3.14159 1.57079 3.14159</pose>
          <geometry>
            <cylinder>
              <length>0.015</length>
              <radius>0.03</radius>
            </cylinder>
          </geometry>
          <surface>
            <contact>
              <ode/>
            </contact>
            <friction>
              <ode/>
              <torsional>
                <ode/>
              </torsional>
            </friction>
            <bounce/>
          </surface>
          <max_contacts>10</max_contacts>
        </collision>
        <collision name='base_link_fixed_joint_lump__dum_left_wheel_collision_8'>
          <pose>0.3 0.175 0 1.5708 -0 0</pose>
          <geometry>
            <cylinder>
              <length>0.04</length>
              <radius>0.05</radius>
            </cylinder>
          </geometry>
          <surface>
            <contact>
              <ode/>
            </contact>
            <friction>
              <ode>
                <mu>0.001</mu>
                <mu2>0.001</mu2>
              </ode>
              <torsional>
                <ode/>
              </torsional>
            </friction>
            <bounce/>
          </surface>
          <max_contacts>10</max_contacts>
        </collision>
        <collision name='base_link_fixed_joint_lump__dum_right_wheel_collision_9'>
          <pose>0.3 -0.175 0 1.5708 -0 0</pose>
          <geometry>
            <cylinder>
              <length>0.04</length>
              <radius>0.05</radius>
            </cylinder>
          </geometry>
          <surface>
            <contact>
              <ode/>
            </contact>
            <friction>
              <ode>
                <mu>0.001</mu>
                <mu2>0.001</mu2>
              </ode>
              <torsional>
                <ode/>
              </torsional>
            </friction>
            <bounce/>
          </surface>
          <max_contacts>10</max_contacts>
        </collision>
        <visual name='base_link_fixed_joint_lump__chassis_visual'>
          <pose>0.2 0 0.075 0 -0 0</pose>
          <geometry>
            <box>
              <size>0.5 0.3 0.15</size>
            </box>
          </geometry>
          <material>
            <script>
              <name>Gazebo/Blue</name>
              <uri>file://media/materials/scripts/gazebo.material</uri>
            </script>
          </material>
        </visual>
        <visual name='base_link_fixed_joint_lump__back_visual_1'>
          <pose>0.15 0 0.22 0 -0 0</pose>
          <geometry>
            <box>
              <size>0.25 0.25 0.14</size>
            </box>
          </geometry>
          <material>
            <script>
              <name>Gazebo/Blue</name>
              <uri>file://media/materials/scripts/gazebo.material</uri>
            </script>
          </material>
        </visual>
        <visual name='base_link_fixed_joint_lump__laser_framenew_visual_2'>
          <pose>0.45 0 0.02 0 -0 0</pose>
          <geometry>
            <cylinder>
              <length>0.01</length>
              <radius>0.01</radius>
            </cylinder>
          </geometry>
          <material>
            <script>
              <name>Gazebo/Red</name>
              <uri>file://media/materials/scripts/gazebo.material</uri>
            </script>
          </material>
        </visual>
        <visual name='base_link_fixed_joint_lump__support_visual_3'>
          <pose>0.37 0 0.16 0 -0 0</pose>
          <geometry>
            <cylinder>
              <length>0.02</length>
              <radius>0.025</radius>
            </cylinder>
          </geometry>
          <material>
            <script>
              <name>Gazebo/Black</name>
              <uri>file://media/materials/scripts/gazebo.material</uri>
            </script>
          </material>
        </visual>
        <visual name='base_link_fixed_joint_lump__support1_visual_4'>
          <pose>0.37 0 0.26 0 -0 0</pose>
          <geometry>
            <cylinder>
              <length>0.18</length>
              <radius>0.025</radius>
            </cylinder>
          </geometry>
          <material>
            <script>
              <name>Gazebo/Orange</name>
              <uri>file://media/materials/scripts/gazebo.material</uri>
            </script>
          </material>
        </visual>
        <visual name='base_link_fixed_joint_lump__box_visual_5'>
          <pose>0.37 0 0.38 0 -0 0</pose>
          <geometry>
            <box>
              <size>0.06 0.12 0.06</size>
            </box>
          </geometry>
          <material>
            <script>
              <name>Gazebo/Blue</name>
              <uri>file://media/materials/scripts/gazebo.material</uri>
            </script>
          </material>
        </visual>
        <visual name='base_link_fixed_joint_lump__face_link_visual_6'>
          <pose>0.4 0.03 0.39 3.14159 1.57079 3.14159</pose>
          <geometry>
            <cylinder>
              <length>0.002</length>
              <radius>0.01</radius>
            </cylinder>
          </geometry>
          <material>
            <script>
              <name>Gazebo/Black</name>
              <uri>file://media/materials/scripts/gazebo.material</uri>
            </script>
          </material>
        </visual>
        <visual name='base_link_fixed_joint_lump__face_link_visual_7'>
          <pose>0.4 -0.03 0.39 3.14159 1.57079 3.14159</pose>
          <geometry>
            <cylinder>
              <length>0.002</length>
              <radius>0.01</radius>
            </cylinder>
          </geometry>
          <material>
            <script>
              <name>Gazebo/Black</name>
              <uri>file://media/materials/scripts/gazebo.material</uri>
            </script>
          </material>
        </visual>
        <visual name='base_link_fixed_joint_lump__laser_frame_visual_8'>
          <pose>0.37 0 0.42 0 -0 0</pose>
          <geometry>
            <cylinder>
              <length>0.02</length>
              <radius>0.02</radius>
            </cylinder>
          </geometry>
          <material>
            <script>
              <name>Gazebo/Red</name>
              <uri>file://media/materials/scripts/gazebo.material</uri>
            </script>
          </material>
        </visual>
        <visual name='base_link_fixed_joint_lump__camera_link_visual_9'>
          <pose>0.37 0 0.43 0 -0 0</pose>
          <geometry>
            <box>
              <size>1e-05 1e-05 1e-05</size>
            </box>
          </geometry>
          <material>
            <script>
              <name>Gazebo/Red</name>
              <uri>file://media/materials/scripts/gazebo.material</uri>
            </script>
          </material>
        </visual>
        <visual name='base_link_fixed_joint_lump__vc2_visual_10'>
          <pose>0.445 0.05 0.05 3.14159 1.57079 3.14159</pose>
          <geometry>
            <cylinder>
              <length>0.015</length>
              <radius>0.03</radius>
            </cylinder>
          </geometry>
          <material>
            <script>
              <name>Gazebo/Black</name>
              <uri>file://media/materials/scripts/gazebo.material</uri>
            </script>
          </material>
        </visual>
        <visual name='base_link_fixed_joint_lump__dum_left_wheel_visual_11'>
          <pose>0.3 0.175 0 1.5708 -0 0</pose>
          <geometry>
            <cylinder>
              <length>0.04</length>
              <radius>0.05</radius>
            </cylinder>
          </geometry>
          <material>
            <script>
              <name>Gazebo/Black</name>
              <uri>file://media/materials/scripts/gazebo.material</uri>
            </script>
          </material>
        </visual>
        <visual name='base_link_fixed_joint_lump__dum_right_wheel_visual_12'>
          <pose>0.3 -0.175 0 1.5708 -0 0</pose>
          <geometry>
            <cylinder>
              <length>0.04</length>
              <radius>0.05</radius>
            </cylinder>
          </geometry>
          <material>
            <script>
              <name>Gazebo/Black</name>
              <uri>file://media/materials/scripts/gazebo.material</uri>
            </script>
          </material>
        </visual>
        <sensor name='laser' type='ray'>
          <visualize>1</visualize>
          <update_rate>4</update_rate>
          <ray>
            <scan>
              <horizontal>
                <samples>10</samples>
                <min_angle>0</min_angle>
                <max_angle>0.1</max_angle>
                <resolution>1</resolution>
              </horizontal>
              <vertical>
                <samples>1</samples>
                <min_angle>0</min_angle>
                <max_angle>0</max_angle>
              </vertical>
            </scan>
            <range>
              <min>0.15</min>
              <max>12</max>
            </range>
          </ray>
          <plugin name='laser_controller' filename='libgazebo_ros_ray_sensor.so'>
            <ros>
              <argument>~/out:=scan</argument>
            </ros>
            <output_type>sensor_msgs/LaserScan</output_type>
            <frame_name>laser_frame</frame_name>
          </plugin>
          <pose>0.45 0 0.02 0 -0 0</pose>
        </sensor>
        <sensor name='camera1' type='multicamera'>
          <update_rate>60</update_rate>
          <visualize>1</visualize>
          <camera name='left'>
            <horizontal_fov>1.39626</horizontal_fov>
            <image>
              <width>640</width>
              <height>480</height>
              <format>R8G8B8</format>
            </image>
            <clip>
              <near>0.02</near>
              <far>300</far>
            </clip>
            <noise>
              <type>gaussian</type>
              <mean>0</mean>
              <stddev>0.007</stddev>
            </noise>
          </camera>
          <camera name='right'>
            <pose>0 0.4 0 0 -0 0</pose>
            <horizontal_fov>0.7</horizontal_fov>
            <image>
              <width>320</width>
              <height>480</height>
              <format>R8G8B8</format>
            </image>
            <clip>
              <near>0.02</near>
              <far>300</far>
            </clip>
            <noise>
              <type>gaussian</type>
              <mean>0</mean>
              <stddev>0.007</stddev>
            </noise>
          </camera>
          <plugin name='camera_controller' filename='libgazebo_ros_camera.so'>
            <ros>
              <namespace>demo_cam</namespace>
              <remapping>mycamera/left/image_raw:=mycamera/left/image_demo</remapping>
              <remapping>mycamera/right/image_raw:=mycamera/right/image_demo</remapping>
              <remapping>mycamera/left/camera_info:=mycamera/left/camera_info_demo</remapping>
              <remapping>mycamera/right/camera_info:=mycamera/right/camera_info_demo</remapping>
            </ros>
            <camera_name>mycamera</camera_name>
          </plugin>
          <pose>0.37 0 0.43 0 -0 0</pose>
        </sensor>
        <sensor name='camera' type='depth'>
          <visualize>1</visualize>
          <update_rate>10</update_rate>
          <camera>
            <horizontal_fov>1.089</horizontal_fov>
            <image>
              <format>B8G8R8</format>
              <width>640</width>
              <height>480</height>
            </image>
            <clip>
              <near>0.05</near>
              <far>8</far>
            </clip>
          </camera>
          <plugin name='camera_controller' filename='libgazebo_ros_camera.so'>
            <frame_name>camera_link_optical</frame_name>
            <min_depth>0.1</min_depth>
            <max_depth>100.0</max_depth>
          </plugin>
          <pose>0.37 0 0.43 0 -0 0</pose>
        </sensor>
        <self_collide>0</self_collide>
        <enable_wind>0</enable_wind>
        <kinematic>0</kinematic>
      </link>
      <joint name='lift_joint' type='prismatic'>
        <pose relative_to='base_link'>0.34 0 -0.0449 0 -0 0</pose>
        <parent>base_link</parent>
        <child>lift</child>
        <axis>
          <xyz>0 0 1</xyz>
          <limit>
            <lower>0</lower>
            <upper>0.11</upper>
            <effort>100</effort>
            <velocity>100</velocity>
          </limit>
          <dynamics>
            <spring_reference>0</spring_reference>
            <spring_stiffness>0</spring_stiffness>
          </dynamics>
        </axis>
      </joint>
      <link name='lift'>
        <pose relative_to='lift_joint'>0 0 0 0 -0 0</pose>
        <inertial>
          <pose>0.15 0 0.002 0 -0 0</pose>
          <mass>0.1</mass>
          <inertia>
            <ixx>0.000750208</ixx>
            <ixy>0</ixy>
            <ixz>0</ixz>
            <iyy>5.35417e-05</iyy>
            <iyz>0</iyz>
            <izz>0.000803333</izz>
          </inertia>
        </inertial>
        <collision name='lift_collision'>
          <pose>0.15 0 0.005 0 -0 0</pose>
          <geometry>
            <box>
              <size>0.08 0.3 1e-05</size>
            </box>
          </geometry>
          <surface>
            <contact>
              <ode/>
            </contact>
            <friction>
              <ode>
                <mu>1e-05</mu>
                <mu2>1e-05</mu2>
              </ode>
              <torsional>
                <ode/>
              </torsional>
            </friction>
            <bounce/>
          </surface>
          <max_contacts>10</max_contacts>
        </collision>
        <visual name='lift_visual'>
          <pose>0.15 0 0.002 0 -0 0</pose>
          <geometry>
            <box>
              <size>0.08 0.3 0.005</size>
            </box>
          </geometry>
          <material>
            <script>
              <name>Gazebo/Black</name>
              <uri>file://media/materials/scripts/gazebo.material</uri>
            </script>
          </material>
        </visual>
        <self_collide>0</self_collide>
        <enable_wind>0</enable_wind>
        <kinematic>0</kinematic>
      </link>
      <joint name='forkone_joint' type='prismatic'>
        <pose relative_to='lift'>0.05 -0.15 0.05 0 -0 0</pose>
        <parent>lift</parent>
        <child>forkone</child>
        <axis>
          <xyz>0 1 0</xyz>
          <limit>
            <lower>0</lower>
            <upper>0.085</upper>
            <effort>1000</effort>
            <velocity>10</velocity>
          </limit>
          <dynamics>
            <spring_reference>0</spring_reference>
            <spring_stiffness>0</spring_stiffness>
          </dynamics>
        </axis>
      </joint>
      <link name='forkone'>
        <pose relative_to='forkone_joint'>0 0 0 0 -0 0</pose>
        <inertial>
          <pose>0.175 0.0125 0.001 0 -0 0</pose>
          <mass>0.2</mass>
          <inertia>
            <ixx>0.00022895</ixx>
            <ixy>-6.25e-05</ixy>
            <ixz>5e-06</ixz>
            <iyy>0.000376033</iyy>
            <iyz>2.5e-06</iyz>
            <izz>0.00027125</izz>
          </inertia>
        </inertial>
        <collision name='forkone_collision'>
          <pose>0.15 0 0.002 0 -0 0</pose>
          <geometry>
            <box>
              <size>0.1 0.01 0.1</size>
            </box>
          </geometry>
          <surface>
            <contact>
              <ode/>
            </contact>
            <friction>
              <ode>
                <mu>0.10001</mu>
                <mu2>0.10001</mu2>
              </ode>
              <torsional>
                <ode/>
              </torsional>
            </friction>
            <bounce/>
          </surface>
          <max_contacts>10</max_contacts>
        </collision>
        <collision name='forkone_fixed_joint_lump__cap1_collision_1'>
          <pose>0.2 0.025 0 0 -0 0</pose>
          <geometry>
            <box>
              <size>0.01 0.06 0.1</size>
            </box>
          </geometry>
          <surface>
            <contact>
              <ode/>
            </contact>
            <friction>
              <ode/>
              <torsional>
                <ode/>
              </torsional>
            </friction>
            <bounce/>
          </surface>
          <max_contacts>10</max_contacts>
        </collision>
        <visual name='forkone_visual'>
          <pose>0.15 0 0.002 0 -0 0</pose>
          <geometry>
            <box>
              <size>0.1 0.01 0.1</size>
            </box>
          </geometry>
          <material>
            <script>
              <name>Gazebo/Black</name>
              <uri>file://media/materials/scripts/gazebo.material</uri>
            </script>
          </material>
        </visual>
        <visual name='forkone_fixed_joint_lump__cap1_visual_1'>
          <pose>0.2 0.025 0 0 -0 0</pose>
          <geometry>
            <box>
              <size>0.01 0.06 0.1</size>
            </box>
          </geometry>
          <material>
            <script>
              <name>Gazebo/Black</name>
              <uri>file://media/materials/scripts/gazebo.material</uri>
            </script>
          </material>
        </visual>
        <self_collide>0</self_collide>
        <enable_wind>0</enable_wind>
        <kinematic>0</kinematic>
      </link>
      <joint name='forktwo_joint' type='prismatic'>
        <pose relative_to='lift'>0.05 0.15 0.05 0 -0 0</pose>
        <parent>lift</parent>
        <child>forktwo</child>
        <axis>
          <xyz>0 -1 0</xyz>
          <limit>
            <lower>0</lower>
            <upper>0.085</upper>
            <effort>1000</effort>
            <velocity>10</velocity>
          </limit>
          <dynamics>
            <spring_reference>0</spring_reference>
            <spring_stiffness>0</spring_stiffness>
          </dynamics>
        </axis>
      </joint>
      <link name='forktwo'>
        <pose relative_to='forktwo_joint'>0 0 0 0 -0 0</pose>
        <inertial>
          <pose>0.175 -0.0125 0.001 0 -0 0</pose>
          <mass>0.2</mass>
          <inertia>
            <ixx>0.000219783</ixx>
            <ixy>6.25e-05</ixy>
            <ixz>5e-06</ixz>
            <iyy>0.000376033</iyy>
            <iyz>-2.5e-06</iyz>
            <izz>0.000262083</izz>
          </inertia>
        </inertial>
        <collision name='forktwo_collision'>
          <pose>0.15 0 0.002 0 -0 0</pose>
          <geometry>
            <box>
              <size>0.1 0.01 0.1</size>
            </box>
          </geometry>
          <surface>
            <contact>
              <ode/>
            </contact>
            <friction>
              <ode>
                <mu>0.10001</mu>
                <mu2>0.10001</mu2>
              </ode>
              <torsional>
                <ode/>
              </torsional>
            </friction>
            <bounce/>
          </surface>
          <max_contacts>10</max_contacts>
        </collision>
        <collision name='forktwo_fixed_joint_lump__cap_collision_1'>
          <pose>0.2 -0.025 0 0 -0 0</pose>
          <geometry>
            <box>
              <size>0.01 0.06 0.1</size>
            </box>
          </geometry>
          <surface>
            <contact>
              <ode/>
            </contact>
            <friction>
              <ode/>
              <torsional>
                <ode/>
              </torsional>
            </friction>
            <bounce/>
          </surface>
          <max_contacts>10</max_contacts>
        </collision>
        <visual name='forktwo_visual'>
          <pose>0.15 0 0.002 0 -0 0</pose>
          <geometry>
            <box>
              <size>0.1 0.01 0.1</size>
            </box>
          </geometry>
          <material>
            <script>
              <name>Gazebo/Black</name>
              <uri>file://media/materials/scripts/gazebo.material</uri>
            </script>
          </material>
        </visual>
        <visual name='forktwo_fixed_joint_lump__cap_visual_1'>
          <pose>0.2 -0.025 0 0 -0 0</pose>
          <geometry>
            <box>
              <size>0.01 0.06 0.1</size>
            </box>
          </geometry>
          <material>
            <script>
              <name>Gazebo/Black</name>
              <uri>file://media/materials/scripts/gazebo.material</uri>
            </script>
          </material>
        </visual>
        <self_collide>0</self_collide>
        <enable_wind>0</enable_wind>
        <kinematic>0</kinematic>
      </link>
      <joint name='vc1_joint' type='prismatic'>
        <pose relative_to='base_link'>0.445 -0.05 0.05 3.14159 1.57079 3.14159</pose>
        <parent>base_link</parent>
        <child>vc1</child>
        <axis>
          <xyz>0 1 0</xyz>
          <limit>
            <lower>0</lower>
            <upper>0</upper>
            <effort>100</effort>
            <velocity>10</velocity>
          </limit>
          <dynamics>
            <spring_reference>0</spring_reference>
            <spring_stiffness>0</spring_stiffness>
          </dynamics>
        </axis>
      </joint>
      <link name='vc1'>
        <pose relative_to='vc1_joint'>0 0 0 0 -0 0</pose>
        <inertial>
          <pose>0 0 0 0 -0 0</pose>
          <mass>0.001</mass>
          <inertia>
            <ixx>2.4375e-07</ixx>
            <ixy>0</ixy>
            <ixz>0</ixz>
            <iyy>2.4375e-07</iyy>
            <iyz>0</iyz>
            <izz>4.5e-07</izz>
          </inertia>
        </inertial>
        <collision name='vc1_collision'>
          <pose>0 0 0 0 -0 0</pose>
          <geometry>
            <cylinder>
              <length>0.015</length>
              <radius>0.03</radius>
            </cylinder>
          </geometry>
          <surface>
            <contact>
              <ode/>
            </contact>
            <friction>
              <ode/>
              <torsional>
                <ode/>
              </torsional>
            </friction>
            <bounce/>
          </surface>
          <max_contacts>10</max_contacts>
        </collision>
        <visual name='vc1_visual'>
          <pose>0 0 0 0 -0 0</pose>
          <geometry>
            <cylinder>
              <length>0.015</length>
              <radius>0.03</radius>
            </cylinder>
          </geometry>
          <material>
            <script>
              <name>Gazebo/Black</name>
              <uri>file://media/materials/scripts/gazebo.material</uri>
            </script>
          </material>
        </visual>
        <self_collide>0</self_collide>
        <enable_wind>0</enable_wind>
        <kinematic>0</kinematic>
      </link>
      <joint name='left_wheel_joint' type='revolute'>
        <pose relative_to='base_link'>0 0.175 0 -1.5708 0 0</pose>
        <parent>base_link</parent>
        <child>left_wheel</child>
        <axis>
          <xyz>0 0 1</xyz>
          <limit>
            <lower>-1e+16</lower>
            <upper>1e+16</upper>
          </limit>
          <dynamics>
            <spring_reference>0</spring_reference>
            <spring_stiffness>0</spring_stiffness>
          </dynamics>
        </axis>
      </joint>
      <link name='left_wheel'>
        <pose relative_to='left_wheel_joint'>0 0 0 0 -0 0</pose>
        <inertial>
          <pose>0 0 0 0 -0 0</pose>
          <mass>1.1</mass>
          <inertia>
            <ixx>0.000834167</ixx>
            <ixy>0</ixy>
            <ixz>0</ixz>
            <iyy>0.000834167</iyy>
            <iyz>0</iyz>
            <izz>0.001375</izz>
          </inertia>
        </inertial>
        <collision name='left_wheel_collision'>
          <pose>0 0 0 0 -0 0</pose>
          <geometry>
            <cylinder>
              <length>0.04</length>
              <radius>0.05</radius>
            </cylinder>
          </geometry>
          <surface>
            <contact>
              <ode/>
            </contact>
            <friction>
              <ode/>
              <torsional>
                <ode/>
              </torsional>
            </friction>
            <bounce/>
          </surface>
          <max_contacts>10</max_contacts>
        </collision>
        <visual name='left_wheel_visual'>
          <pose>0 0 0 0 -0 0</pose>
          <geometry>
            <cylinder>
              <length>0.04</length>
              <radius>0.05</radius>
            </cylinder>
          </geometry>
          <material>
            <script>
              <name>Gazebo/Black</name>
              <uri>file://media/materials/scripts/gazebo.material</uri>
            </script>
          </material>
        </visual>
        <self_collide>0</self_collide>
        <enable_wind>0</enable_wind>
        <kinematic>0</kinematic>
      </link>
      <joint name='right_wheel_joint' type='revolute'>
        <pose relative_to='base_link'>0 -0.175 0 1.5708 -0 0</pose>
        <parent>base_link</parent>
        <child>right_wheel</child>
        <axis>
          <xyz>0 0 -1</xyz>
          <limit>
            <lower>-1e+16</lower>
            <upper>1e+16</upper>
          </limit>
          <dynamics>
            <spring_reference>0</spring_reference>
            <spring_stiffness>0</spring_stiffness>
          </dynamics>
        </axis>
      </joint>
      <link name='right_wheel'>
        <pose relative_to='right_wheel_joint'>0 0 0 0 -0 0</pose>
        <inertial>
          <pose>0 0 0 0 -0 0</pose>
          <mass>1.1</mass>
          <inertia>
            <ixx>0.00190667</ixx>
            <ixy>0</ixy>
            <ixz>0</ixz>
            <iyy>0.00190667</iyy>
            <iyz>0</iyz>
            <izz>0.00352</izz>
          </inertia>
        </inertial>
        <collision name='right_wheel_collision'>
          <pose>0 0 0 0 -0 0</pose>
          <geometry>
            <cylinder>
              <length>0.04</length>
              <radius>0.05</radius>
            </cylinder>
          </geometry>
          <max_contacts>10</max_contacts>
          <surface>
            <contact>
              <ode/>
            </contact>
            <bounce/>
            <friction>
              <torsional>
                <ode/>
              </torsional>
              <ode/>
            </friction>
          </surface>
        </collision>
        <visual name='right_wheel_visual'>
          <pose>0 0 0 0 -0 0</pose>
          <geometry>
            <cylinder>
              <length>0.04</length>
              <radius>0.05</radius>
            </cylinder>
          </geometry>
        </visual>
        <self_collide>0</self_collide>
        <enable_wind>0</enable_wind>
        <kinematic>0</kinematic>
      </link>
      <plugin name='gazebo_ros_joint_pose_trajectory' filename='libgazebo_ros_joint_pose_trajectory.so'>
        <ros>
          <namespace>/vision</namespace>
          <remapping>set_joint_trajectory:=set_trajectory_demo</remapping>
        </ros>
        <update_rate>2</update_rate>
      </plugin>
      <plugin name='vacuum_gripper' filename='libgazebo_ros_vacuum_gripper.so'>
        <ros>
          <namespace>/demo</namespace>
          <remapping>switch:=switch_demo</remapping>
          <remapping>grasping:=grasping_demo</remapping>
        </ros>
        <link_name>vc1</link_name>
        <max_distance>0.8</max_distance>
        <fixed>base_link</fixed>
      </plugin>
      <plugin name='vacuum_gripper' filename='libgazebo_ros_vacuum_gripper.so'>
        <ros>
          <namespace>/demo1</namespace>
          <remapping>switch:=switch_demo</remapping>
          <remapping>grasping:=grasping_demo</remapping>
        </ros>
        <link_name>vc2</link_name>
        <max_distance>0.8</max_distance>
        <fixed>base_link</fixed>
      </plugin>
      <plugin name='vacuum_gripper' filename='libgazebo_ros_vacuum_gripper.so'>
        <ros>
          <namespace>/fork</namespace>
          <remapping>switch:=switch_demo</remapping>
          <remapping>grasping:=grasping_demo</remapping>
        </ros>
        <link_name>forkone</link_name>
        <max_distance>0.1</max_distance>
        <fixed>base_link</fixed>
      </plugin>
      <static>0</static>
      <plugin name='gazebo_ros2_control' filename='libgazebo_ros2_control.so'>
        <parameters>/home/dhanush/Desktop/ros2_ws/install/vision/share/vision/config/my_controllers.yaml</parameters>
      </plugin>
      <pose>0 0 0 0 -0 0</pose>
    </model>
    <model name='unit_cylinder'>
      <pose>1.31371 1.14626 0.5 0 -0 0</pose>
      <link name='link'>
        <inertial>
          <mass>1</mass>
          <inertia>
            <ixx>0.145833</ixx>
            <ixy>0</ixy>
            <ixz>0</ixz>
            <iyy>0.145833</iyy>
            <iyz>0</iyz>
            <izz>0.125</izz>
          </inertia>
          <pose>0 0 0 0 -0 0</pose>
        </inertial>
        <collision name='collision'>
          <geometry>
            <cylinder>
              <radius>0.500001</radius>
              <length>1</length>
            </cylinder>
          </geometry>
          <max_contacts>10</max_contacts>
          <surface>
            <contact>
              <ode/>
            </contact>
            <bounce/>
            <friction>
              <torsional>
                <ode/>
              </torsional>
              <ode/>
            </friction>
          </surface>
        </collision>
        <visual name='visual'>
          <geometry>
            <cylinder>
              <radius>0.500001</radius>
              <length>1</length>
            </cylinder>
          </geometry>
          <material>
            <script>
              <name>Gazebo/Grey</name>
              <uri>file://media/materials/scripts/gazebo.material</uri>
            </script>
          </material>
        </visual>
        <self_collide>0</self_collide>
        <enable_wind>0</enable_wind>
        <kinematic>0</kinematic>
      </link>
    </model>
    <model name='unit_sphere'>
      <pose>3.19984 2.14683 0.5 0 -0 0</pose>
      <link name='link'>
        <inertial>
          <mass>1</mass>
          <inertia>
            <ixx>0.1</ixx>
            <ixy>0</ixy>
            <ixz>0</ixz>
            <iyy>0.1</iyy>
            <iyz>0</iyz>
            <izz>0.1</izz>
          </inertia>
          <pose>0 0 0 0 -0 0</pose>
        </inertial>
        <collision name='collision'>
          <geometry>
            <sphere>
              <radius>0.5</radius>
            </sphere>
          </geometry>
          <max_contacts>10</max_contacts>
          <surface>
            <contact>
              <ode/>
            </contact>
            <bounce/>
            <friction>
              <torsional>
                <ode/>
              </torsional>
              <ode/>
            </friction>
          </surface>
        </collision>
        <visual name='visual'>
          <geometry>
            <sphere>
              <radius>0.5</radius>
            </sphere>
          </geometry>
          <material>
            <script>
              <name>Gazebo/Grey</name>
              <uri>file://media/materials/scripts/gazebo.material</uri>
            </script>
          </material>
        </visual>
        <self_collide>0</self_collide>
        <enable_wind>0</enable_wind>
        <kinematic>0</kinematic>
      </link>
    </model>
    <model name='unit_box'>
      <pose>-1.32463 3.28145 0.5 0 -0 0</pose>
      <link name='link'>
        <inertial>
          <mass>1</mass>
          <inertia>
            <ixx>0.166667</ixx>
            <ixy>0</ixy>
            <ixz>0</ixz>
            <iyy>0.166667</iyy>
            <iyz>0</iyz>
            <izz>0.166667</izz>
          </inertia>
          <pose>0 0 0 0 -0 0</pose>
        </inertial>
        <collision name='collision'>
          <geometry>
            <box>
              <size>1 0.999999 1</size>
            </box>
          </geometry>
          <max_contacts>10</max_contacts>
          <surface>
            <contact>
              <ode/>
            </contact>
            <bounce/>
            <friction>
              <torsional>
                <ode/>
              </torsional>
              <ode/>
            </friction>
          </surface>
        </collision>
        <visual name='visual'>
          <geometry>
            <box>
              <size>1 0.999999 1</size>
            </box>
          </geometry>
          <material>
            <script>
              <name>Gazebo/Grey</name>
              <uri>file://media/materials/scripts/gazebo.material</uri>
            </script>
          </material>
        </visual>
        <self_collide>0</self_collide>
        <enable_wind>0</enable_wind>
        <kinematic>0</kinematic>
      </link>
    </model>
    <model name='unit_sphere_clone'>
      <pose>-3.13585 1.0396 0.060022 0 -0 0</pose>
      <link name='link'>
        <inertial>
          <mass>1</mass>
          <inertia>
            <ixx>0.1</ixx>
            <ixy>0</ixy>
            <ixz>0</ixz>
            <iyy>0.1</iyy>
            <iyz>0</iyz>
            <izz>0.1</izz>
          </inertia>
          <pose>0 0 0 0 -0 0</pose>
        </inertial>
        <collision name='collision'>
          <geometry>
            <sphere>
              <radius>0.0600225</radius>
            </sphere>
          </geometry>
          <max_contacts>10</max_contacts>
          <surface>
            <contact>
              <ode/>
            </contact>
            <bounce/>
            <friction>
              <torsional>
                <ode/>
              </torsional>
              <ode/>
            </friction>
          </surface>
        </collision>
        <visual name='visual'>
          <geometry>
            <sphere>
              <radius>0.0600225</radius>
            </sphere>
          </geometry>
          <material>
            <script>
              <name>Gazebo/Grey</name>
              <uri>file://media/materials/scripts/gazebo.material</uri>
            </script>
          </material>
        </visual>
        <self_collide>0</self_collide>
        <enable_wind>0</enable_wind>
        <kinematic>0</kinematic>
      </link>
    </model>
    <model name='unit_cylinder_clone'>
      <pose>-1 2 0.048951 1.5708 0 6e-06</pose>
      <link name='link'>
        <inertial>
          <mass>1</mass>
          <inertia>
            <ixx>0.145833</ixx>
            <ixy>0</ixy>
            <ixz>0</ixz>
            <iyy>0.145833</iyy>
            <iyz>0</iyz>
            <izz>0.125</izz>
          </inertia>
          <pose>0 0 0 0 -0 0</pose>
        </inertial>
        <collision name='collision'>
          <geometry>
            <cylinder>
              <radius>0.0489506</radius>
              <length>0.0827204</length>
            </cylinder>
          </geometry>
          <max_contacts>10</max_contacts>
          <surface>
            <contact>
              <ode/>
            </contact>
            <bounce/>
            <friction>
              <torsional>
                <ode/>
              </torsional>
              <ode/>
            </friction>
          </surface>
        </collision>
        <visual name='visual'>
          <geometry>
            <cylinder>
              <radius>0.0489506</radius>
              <length>0.0827204</length>
            </cylinder>
          </geometry>
          <material>
            <script>
              <name>Gazebo/Grey</name>
              <uri>file://media/materials/scripts/gazebo.material</uri>
            </script>
          </material>
        </visual>
        <self_collide>0</self_collide>
        <enable_wind>0</enable_wind>
        <kinematic>0</kinematic>
      </link>
    </model>
    <model name='unit_sphere_clone_clone'>
      <pose>-3.22688 -1.34186 0.060022 0 -0 0</pose>
      <link name='link'>
        <inertial>
          <mass>1</mass>
          <inertia>
            <ixx>0.1</ixx>
            <ixy>0</ixy>
            <ixz>0</ixz>
            <iyy>0.1</iyy>
            <iyz>0</iyz>
            <izz>0.1</izz>
          </inertia>
          <pose>0 0 0 0 -0 0</pose>
        </inertial>
        <collision name='collision'>
          <geometry>
            <sphere>
              <radius>0.0600225</radius>
            </sphere>
          </geometry>
          <max_contacts>10</max_contacts>
          <surface>
            <contact>
              <ode/>
            </contact>
            <bounce/>
            <friction>
              <torsional>
                <ode/>
              </torsional>
              <ode/>
            </friction>
          </surface>
        </collision>
        <visual name='visual'>
          <geometry>
            <sphere>
              <radius>0.0600225</radius>
            </sphere>
          </geometry>
          <material>
            <script>
              <name>Gazebo/Grey</name>
              <uri>file://media/materials/scripts/gazebo.material</uri>
            </script>
          </material>
        </visual>
        <self_collide>0</self_collide>
        <enable_wind>0</enable_wind>
        <kinematic>0</kinematic>
      </link>
    </model>
    <model name='unit_sphere_clone_clone_0'>
      <pose>0.232744 -3.05774 0.060022 0 -0 0</pose>
      <link name='link'>
        <inertial>
          <mass>1</mass>
          <inertia>
            <ixx>0.1</ixx>
            <ixy>0</ixy>
            <ixz>0</ixz>
            <iyy>0.1</iyy>
            <iyz>0</iyz>
            <izz>0.1</izz>
          </inertia>
          <pose>0 0 0 0 -0 0</pose>
        </inertial>
        <collision name='collision'>
          <geometry>
            <sphere>
              <radius>0.0600225</radius>
            </sphere>
          </geometry>
          <max_contacts>10</max_contacts>
          <surface>
            <contact>
              <ode/>
            </contact>
            <bounce/>
            <friction>
              <torsional>
                <ode/>
              </torsional>
              <ode/>
            </friction>
          </surface>
        </collision>
        <visual name='visual'>
          <geometry>
            <sphere>
              <radius>0.0600225</radius>
            </sphere>
          </geometry>
          <material>
            <script>
              <name>Gazebo/Grey</name>
              <uri>file://media/materials/scripts/gazebo.material</uri>
            </script>
          </material>
        </visual>
        <self_collide>0</self_collide>
        <enable_wind>0</enable_wind>
        <kinematic>0</kinematic>
      </link>
    </model>
    <model name='unit_box_clone'>
      <pose>-2.14117 -2.49558 0.057421 -3e-06 1e-06 3e-06</pose>
      <link name='link'>
        <inertial>
          <mass>1</mass>
          <inertia>
            <ixx>0.166667</ixx>
            <ixy>0</ixy>
            <ixz>0</ixz>
            <iyy>0.166667</iyy>
            <iyz>0</iyz>
            <izz>0.166667</izz>
          </inertia>
          <pose>0 0 0 0 -0 0</pose>
        </inertial>
        <collision name='collision'>
          <geometry>
            <box>
              <size>0.214069 0.176378 0.114842</size>
            </box>
          </geometry>
          <max_contacts>10</max_contacts>
          <surface>
            <contact>
              <ode/>
            </contact>
            <bounce/>
            <friction>
              <torsional>
                <ode/>
              </torsional>
              <ode/>
            </friction>
          </surface>
        </collision>
        <visual name='visual'>
          <geometry>
            <box>
              <size>0.214069 0.176378 0.114842</size>
            </box>
          </geometry>
          <material>
            <script>
              <name>Gazebo/Grey</name>
              <uri>file://media/materials/scripts/gazebo.material</uri>
            </script>
          </material>
        </visual>
        <self_collide>0</self_collide>
        <enable_wind>0</enable_wind>
        <kinematic>0</kinematic>
      </link>
    </model>
    <state world_name='default'>
      <sim_time>930 899000000</sim_time>
      <real_time>1177 778020481</real_time>
      <wall_time>1687881395 832036129</wall_time>
      <iterations>930899</iterations>
      <model name='ground_plane'>
        <pose>0 0 0 0 -0 0</pose>
        <scale>1 1 1</scale>
        <link name='link'>
          <pose>0 0 0 0 -0 0</pose>
          <velocity>0 0 0 0 -0 0</velocity>
          <acceleration>0 0 0 0 -0 0</acceleration>
          <wrench>0 0 0 0 -0 0</wrench>
        </link>
      </model>
      <model name='ros2_ws'>
        <pose>1.84651 0.359912 0.05 0 1e-06 0.011779</pose>
        <scale>1 1 1</scale>
        <link name='base_link'>
          <pose>1.84651 0.359912 0.05 0 1e-06 0.011779</pose>
          <velocity>0.001576 -1e-06 -3e-05 0.000144 -0.019334 2.1e-05</velocity>
          <acceleration>-0.266668 -0.011822 8.17564 0.12765 -0.882564 0.007854</acceleration>
          <wrench>-3.49655 -0.155007 107.199 0 -0 0</wrench>
        </link>
        <link name='forkone'>
          <pose>2.23834 0.214764 0.055128 2.3e-05 0.000512 0.011784</pose>
          <velocity>-0.006868 -0.000557 -0.038972 0.003094 -0.216446 0.003718</velocity>
          <acceleration>-14.0109 -0.1652 -3.31756 0.161148 -1.43883 -1.91953</acceleration>
          <wrench>-2.80217 -0.03304 -0.663512 0 -0 0</wrench>
        </link>
        <link name='forktwo'>
          <pose>2.23481 0.51409 0.055109 -1.9e-05 0.000354 0.011774</pose>
          <velocity>-0.00546 0.000758 -0.03445 0.010529 -0.18469 -0.002687</velocity>
          <acceleration>-10.3992 -0.122437 -8.61406 1.42637 -0.638679 -0.714134</acceleration>
          <wrench>-2.07985 -0.024487 -1.72281 0 -0 0</wrench>
        </link>
        <link name='left_wheel'>
          <pose>1.84445 0.534899 0.05 1.57081 -0.327909 -3.12982</pose>
          <velocity>0.001564 -4e-06 -2e-06 0.00012 0.03121 0.00015</velocity>
          <acceleration>3.21289 0.01832 -0.021083 0.322374 0.975979 0.158721</acceleration>
          <wrench>3.53418 0.020152 -0.023191 0 -0 0</wrench>
        </link>
        <link name='lift'>
          <pose>2.18655 0.363917 0.005174 1e-05 0.000607 0.011781</pose>
          <velocity>0.003428 -0.000571 -0.04906 0.004328 -0.214857 0.001832</velocity>
          <acceleration>-0.403839 -0.403909 -25.0963 0.479489 -1.43843 1.12162</acceleration>
          <wrench>-0.040384 -0.040391 -2.50963 0 -0 0</wrench>
        </link>
        <link name='right_wheel'>
          <pose>1.84857 0.184924 0.05 1.5709 1.47037 0.011879</pose>
          <velocity>0.001559 1.1e-05 -3e-06 -0.000259 0.031113 -0.000174</velocity>
          <acceleration>3.18988 0.033424 0.005169 -0.047766 0.144217 -0.420151</acceleration>
          <wrench>3.50887 0.036767 0.005685 0 -0 0</wrench>
        </link>
        <link name='vc1'>
          <pose>2.29207 0.315157 0.1 3.02664 1.5707 3.03843</pose>
          <velocity>0.000826 2.6e-05 0.004061 0.005228 0.02781 -0.001448</velocity>
          <acceleration>1.72623 0.127505 8.81649 -1.192 -0.59618 2.6377</acceleration>
          <wrench>0.001726 0.000128 0.008816 0 -0 0</wrench>
        </link>
      </model>
      <model name='unit_box'>
        <pose>-1.32463 3.28145 0.05742 3e-06 -4e-06 2e-06</pose>
        <scale>0.214069 0.176378 0.114842</scale>
        <link name='link'>
          <pose>-1.32463 3.28145 0.05742 3e-06 -4e-06 2e-06</pose>
          <velocity>0 0 0 0 -0 0</velocity>
          <acceleration>-0.274172 -0.225899 -2.21797 -2.34911 1.50844 -0</acceleration>
          <wrench>-0.274172 -0.225899 -2.21797 0 -0 0</wrench>
        </link>
      </model>
      <model name='unit_box_clone'>
        <pose>-2.14117 -2.49558 0.05742 -5e-06 2e-06 2e-06</pose>
        <scale>1 1 1</scale>
        <link name='link'>
          <pose>-2.14117 -2.49558 0.05742 -5e-06 2e-06 2e-06</pose>
          <velocity>0 0 0 0 -0 0</velocity>
          <acceleration>0.274172 0.2259 -2.21797 2.3491 -1.50844 0</acceleration>
          <wrench>0.274172 0.2259 -2.21797 0 -0 0</wrench>
        </link>
      </model>
      <model name='unit_cylinder'>
        <pose>1.31371 1.14485 0.048941 1.57079 0 6e-06</pose>
        <scale>0.097901 0.097901 0.08272</scale>
        <link name='link'>
          <pose>1.31371 1.14485 0.048941 1.57079 0 6e-06</pose>
          <velocity>0 0 0 0 -0 0</velocity>
          <acceleration>0 0 -9.8 0 -0 0</acceleration>
          <wrench>0 0 -9.8 0 -0 0</wrench>
        </link>
      </model>
      <model name='unit_cylinder_clone'>
        <pose>-1 2 0.048952 1.57077 -0 6e-06</pose>
        <scale>1 1 1</scale>
        <link name='link'>
          <pose>-1 2 0.048952 1.57077 -0 6e-06</pose>
          <velocity>0 0 0 0 -0 0</velocity>
          <acceleration>1e-06 -0.124007 -0.720587 2.53336 1.5e-05 0</acceleration>
          <wrench>1e-06 -0.124007 -0.720587 0 -0 0</wrench>
        </link>
      </model>
      <model name='unit_sphere'>
        <pose>3.19984 2.14683 0.060022 0 -0 0</pose>
        <scale>0.120045 0.120045 0.120045</scale>
        <link name='link'>
          <pose>3.19984 2.14683 0.060022 0 -0 0</pose>
          <velocity>0 0 0 0 -0 0</velocity>
          <acceleration>0 0 0 0 -0 0</acceleration>
          <wrench>0 0 0 0 -0 0</wrench>
        </link>
      </model>
      <model name='unit_sphere_clone'>
        <pose>-3.13585 1.0396 0.060022 0 -0 0</pose>
        <scale>1 1 1</scale>
        <link name='link'>
          <pose>-3.13585 1.0396 0.060022 0 -0 0</pose>
          <velocity>0 0 0 0 -0 0</velocity>
          <acceleration>0 0 0 0 -0 0</acceleration>
          <wrench>0 0 0 0 -0 0</wrench>
        </link>
      </model>
      <model name='unit_sphere_clone_clone'>
        <pose>-3.22688 -1.34186 0.060022 0 -0 0</pose>
        <scale>1 1 1</scale>
        <link name='link'>
          <pose>-3.22688 -1.34186 0.060022 0 -0 0</pose>
          <velocity>0 0 0 0 -0 0</velocity>
          <acceleration>0 0 0 0 -0 0</acceleration>
          <wrench>0 0 0 0 -0 0</wrench>
        </link>
      </model>
      <model name='unit_sphere_clone_clone_0'>
        <pose>0.232744 -3.05774 0.060022 0 -0 0</pose>
        <scale>1 1 1</scale>
        <link name='link'>
          <pose>0.232744 -3.05774 0.060022 0 -0 0</pose>
          <velocity>0 0 0 0 -0 0</velocity>
          <acceleration>0 0 0 0 -0 0</acceleration>
          <wrench>0 0 0 0 -0 0</wrench>
        </link>
      </model>
      <light name='sun'>
        <pose>0 0 10 0 -0 0</pose>
      </light>
    </state>
    <gui fullscreen='0'>
      <camera name='user_camera'>
        <pose>9.6028 0.966956 2.23329 0 0.064 3.07759</pose>
        <view_controller>orbit</view_controller>
        <projection_type>perspective</projection_type>
      </camera>
    </gui>
  </world>
</sdf>
